Workbook

Sheet RAM Retail Price
A1: Type | B1: Date | C1: Price (USD/GB) | D1: Description
A2: DDR4 | B2: 44927 | C2: 2.000 | D2: 1x 32GB SO-DIMM DDR4-2666 @ $61.99 + $1.99 shipping
A3: DDR4 | B3: 44956 | C3: 1.800 | D3: 2x 32GB SO-DIMM DDR4-3200 @ $114.99 + free shipping
A4: DDR4 | B4: 44989 | C4: 1.800 | D4: 2x 32GB SO-DIMM DDR4-3200 @ $114.99 + free shipping
A5: DDR4 | B5: 45047 | C5: 1.500 | D5: 2x 32GB SO-DIMM DDR4-3200 @ $97.99 + free shipping
A6: DDR4 | B6: 45080 | C6: 1.430 | D6: 2x 32GB DIMM DDR4-2666 @ $93.99 + free shipping
A7: DDR4 | B7: 45109 | C7: 1.400 | D7: 2x 16GB SO-DIMM DDR4-3200 @ $45.99 + free shipping
A8: DDR4 | B8: 45172 | C8: 1.420 | D8: 2x 32GB DIMM DDR4-3200 @ $92.99 + free shipping
A9: DDR4 | B9: 45201 | C9: 1.370 | D9: 2x 32GB SO-DIMM DDR4-3200 @ $89.99 + free shipping
A10: DDR4 | B10: 45230 | C10: 1.280 | D10: 2x 16GB SO-DIMM DDR4-2666 @ $41.99 + free shipping
A11: DDR4 | B11: 45292 | C11: 1.570 | D11: 2x 32GB SO-DIMM DDR4-3200 @ $102.99 + free shipping
A12: DDR4 | B12: 45321 | C12: 1.680 | D12: 2x 32GB SO-DIMM DDR4-3200 @ $109.99 + free shipping
A13: DDR4 | B13: 45354 | C13: 1.530 | D13: 2x 32GB DIMM DDR4-2666 @ $99.99 + free shipping
... A67: DDR5 | B67: 46266 | C67: 13.41 | D67: Adamanta 64GB (2x32GB) Compatible for ASUS ProArt StudioBook 16 OLED H7600, H7600ZM Laptop

Sheet Company Revenue Summary
A1: Name | B1: Cost Estimate
A2: Google | B2: =SUMIF('Company Revenue'!B2:B132, "Google", 'Company Revenue'!H2:H132) -> 21030533052
A3: Nvidia | B3: =SUMIF('Company Revenue'!B3:B133, "Nvidia", 'Company Revenue'!H3:H133) -> 238070935000
A4: AMD | B4: =SUMIF('Company Revenue'!B4:B134, "AMD", 'Company Revenue'!H4:H134) -> 12534591200
A5: Huawei | B5: =SUMIF('Company Revenue'!B4:B134, "Huawei", 'Company Revenue'!H4:H134) -> 22000000000
A6: Amazon | B6: =SUMIF('Company Revenue'!B4:B134, "Amazon", 'Company Revenue'!H4:H134) -> 5560000000
A7: Total | B7: =SUM(B2:B6) -> 299196059252

Sheet Company Revenue
A1: Quarter | B1: Chip manufacturer | C1: Chip type | D1: Start date | E1: End date | F1: Number of Units | G1: Chip Cost (USD) | H1: Cost Estimate (USD)
A2: Q1 2024 | B2: Google | C2: TPU v5e | D2: 45292 | E2: 45382 | F2: 417187 | G2: 2704.0 | H2: 1128073648
A3: Q1 2024 | B3: Google | C3: TPU v5p | D3: 45292 | E3: 45382 | F3: 83355 | G3: 6022.0 | H3: 501963810
A4: Q1 2024 | B4: Nvidia | C4: H100 | D4: 45292 | E4: 45382 | F4: 552252 | G4: 25000.0 | H4: 13806300000
A5: Q1 2024 | B5: Nvidia | C5: H20 | D5: 45292 | E5: 45382 | F5: 138719 | G5: 12000.0 | H5: 1664628000
A6: Q1 2024 | B6: AMD | C6: Instinct MI250X | D6: 45292 | E6: 45382 | F6: 30379 | G6: 10000.0 | H6: 303790000
A7: Q1 2024 | B7: AMD | C7: Instinct MI300X | D7: 45292 | E7: 45382 | F7: 34535 | G7: 12500.0 | H7: 431687500
A8: Q1 2024 | B8: AMD | C8: Instinct MI300A | D8: 45292 | E8: 45382 | F8: 3562 | G8: 6700.0 | H8: 23865400
A9: Q1 2024 | B9: Huawei | C9: Ascend 910B | D9: 45292 | E9: 45382 | F9: 100000 | G9: 15000.0 | H9: 1500000000
A10: Q1 2024 | B10: Huawei | C10: Ascend 910C | D10: 45292 | E10: 45382 | F10: 12500 | G10: 20000.0 | H10: 250000000
A11: Q1 2024 | B11: Amazon | C11: Trainium1 | D11: 45292 | E11: 45382 | F11: 110000 | H11: 0
A12: Q1 2024 | B12: Amazon | C12: Trainium2 | D12: 45292 | E12: 45382 | F12: 15000 | G12: 4000.0 | H12: 60000000
A13: Q1 2024 | B13: Cambricon | C13: Siyuan 590 | D13: 45292 | E13: 45382 | F13: 547 | H13: 0
A14: Q2 2024 | B14: Google | C14: TPU v5e | D14: 45383 | E14: 45473 | F14: 374471 | G14: 2704.0 | H14: 1012569584
A15: Q2 2024 | B15: Google | C15: TPU v5p | D15: 45383 | E15: 45473 | F15: 144145 | G15: 6022.0 | H15: 868041190
A16: Q2 2024 | B16: Nvidia | C16: H100 | D16: 45383 | E16: 45473 | F16: 650874 | G16: 25000.0 | H16: 16271850000
A17: Q2 2024 | B17: Nvidia | C17: H20 | D17: 45383 | E17: 45473 | F17: 223064 | G17: 12000.0 | H17: 2676768000
A18: Q2 2024 | B18: AMD | C18: Instinct MI250X | D18: 45383 | E18: 45473 | F18: 6596 | G18: 10000.0 | H18: 65960000
A19: Q2 2024 | B19: AMD | C19: Instinct MI300X | D19: 45383 | E19: 45473 | F19: 80709 | G19: 12500.0 | H19: 1008862500
A20: Q2 2024 | B20: AMD | C20: Instinct MI300A | D20: 45383 | E20: 45473 | F20: 10732 | G20: 6700.0 | H20: 71904400
A21: Q2 2024 | B21: Huawei | C21: Ascend 910B | D21: 45383 | E21: 45473 | F21: 100000 | G21: 15000.0 | H21: 1500000000
A22: Q2 2024 | B22: Huawei | C22: Ascend 910C | D22: 45383 | E22: 45473 | F22: 12500 | G22: 20000.0 | H22: 250000000
A23: Q2 2024 | B23: Amazon | C23: Trainium1 | D23: 45383 | E23: 45473 | F23: 110000 | H23: 0
A24: Q2 2024 | B24: Amazon | C24: Trainium2 | D24: 45383 | E24: 45473 | F24: 30000 | G24: 4000.0 | H24: 120000000
A25: Q2 2024 | B25: Cambricon | C25: Siyuan 590 | D25: 45383 | E25: 45473 | F25: 832 | H25: 0
A26: Q3 2024 | B26: Google | C26: TPU v5e | D26: 45474 | E26: 45565 | F26: 356808 | G26: 2704.0 | H26: 964808832
A27: Q3 2024 | B27: Google | C27: TPU v5p | D27: 45474 | E27: 45565 | F27: 159613 | G27: 6022.0 | H27: 961189486
A28: Q3 2024 | B28: Google | C28: TPU v6e | D28: 45474 | E28: 45565 | F28: 40715 | G28: 4059.0 | H28: 165262185
A29: Q3 2024 | B29: Nvidia | C29: H100 | D29: 45474 | E29: 45565 | F29: 794383 | G29: 25000.0 | H29: 19859575000
A30: Q3 2024 | B30: Nvidia | C30: H20 | D30: 45474 | E30: 45565 | F30: 272247 | G30: 12000.0 | H30: 3266964000
A31: Q3 2024 | B31: AMD | C31: Instinct MI250X | D31: 45474 | E31: 45565 | F31: 4385 | G31: 10000.0 | H31: 43850000
A32: Q3 2024 | B32: AMD | C32: Instinct MI300X | D32: 45474 | E32: 45565 | F32: 95258 | G32: 12500.0 | H32: 1190725000
A33: Q3 2024 | B33: AMD | C33: Instinct MI300A | D33: 45474 | E33: 45565 | F33: 43161 | G33: 6700.0 | H33: 289178700
A34: Q3 2024 | B34: Huawei | C34: Ascend 910B | D34: 45474 | E34: 45565 | F34: 100000 | G34: 15000.0 | H34: 1500000000
A35: Q3 2024 | B35: Huawei | C35: Ascend 910C | D35: 45474 | E35: 45565 | F35: 12500 | G35: 20000.0 | H35: 250000000
A36: Q3 2024 | B36: Amazon | C36: Trainium1 | D36: 45474 | E36: 45565 | F36: 110000 | H36: 0
A37: Q3 2024 | B37: Amazon | C37: Trainium2 | D37: 45474 | E37: 45565 | F37: 80000 | G37: 4000.0 | H37: 320000000
A38: Q3 2024 | B38: Cambricon | C38: Siyuan 590 | D38: 45474 | E38: 45565 | F38: 2565 | H38: 0
A39: Q4 2024 | B39: Google | C39: TPU v5e | D39: 45566 | E39: 45657 | F39: 300383 | G39: 2704.0 | H39: 812235632
A40: Q4 2024 | B40: Google | C40: TPU v5p | D40: 45566 | E40: 45657 | F40: 134088 | G40: 6022.0 | H40: 807477936
...

Sheet Company Spending Summary
A1: Q4 2025 Designer Cost Breakdown (Median Estimates)
A3: Designer | B3: Logic Cost | C3: CoWoS Cost | D3: HBM Cost | E3: Auxiliary Cost | F3: Total Est. Cost
A4: ='[1]Quarterly Data'!C26 -> AMD | B4: =SUM('Company Spending Data'!E2, 'Company Spending Data'!E6, 'Company Spending Data'!E10, 'Company Spending Data'!E14, 'Company Spending Data'!E18, 'Company Spending Data'!E22, 'Company Spending Data'!E26, 'Company Spending Data'!E30,) -> 4.1632066e+08 | C4: =SUM('Company Spending Data'!F2, 'Company Spending Data'!F6, 'Company Spending Data'!F10, 'Company Spending Data'!F14, 'Company Spending Data'!F18, 'Company Spending Data'!F22, 'Company Spending Data'!F26, 'Company Spending Data'!F30,) -> 1.2505624e+09 | D4: =SUM('Company Spending Data'!G2, 'Company Spending Data'!G6, 'Company Spending Data'!G10, 'Company Spending Data'!G14, 'Company Spending Data'!G18, 'Company Spending Data'!G22, 'Company Spending Data'!G26, 'Company Spending Data'!G30,) -> 4.2643346e+09 | E4: =SUM('Company Spending Data'!H2, 'Company Spending Data'!H6, 'Company Spending Data'!H10, 'Company Spending Data'!H14, 'Company Spending Data'!H18, 'Company Spending Data'!H22, 'Company Spending Data'!H26, 'Company Spending Data'!H30,) -> 5.4555602e+08 | F4: =SUM(B4:E4) -> 6.4767736e+09
A5: ='[1]Quarterly Data'!C27 -> Amazon | B5: =SUM('Company Spending Data'!E3, 'Company Spending Data'!E7, 'Company Spending Data'!E11, 'Company Spending Data'!E15, 'Company Spending Data'!E19, 'Company Spending Data'!E23, 'Company Spending Data'!E27, 'Company Spending Data'!E31,) -> 7.2936348e+08 | C5: =SUM('Company Spending Data'!F3, 'Company Spending Data'!F7, 'Company Spending Data'!F11, 'Company Spending Data'!F15, 'Company Spending Data'!F19, 'Company Spending Data'!F23, 'Company Spending Data'!F27, 'Company Spending Data'!F31,) -> 9.2836699e+08 | D5: =SUM('Company Spending Data'!G3, 'Company Spending Data'!G7, 'Company Spending Data'!G11, 'Company Spending Data'!G15, 'Company Spending Data'!G19, 'Company Spending Data'!G23, 'Company Spending Data'!G27, 'Company Spending Data'!G31,) -> 2.8170144e+09 | E5: =SUM('Company Spending Data'!H3, 'Company Spending Data'!H7, 'Company Spending Data'!H11, 'Company Spending Data'!H15, 'Company Spending Data'!H19, 'Company Spending Data'!H23, 'Company Spending Data'!H27, 'Company Spending Data'!H31,) -> 7.1281184e+08 | F5: =SUM(B5:E5) -> 5.1875567e+09
A6: ='[1]Quarterly Data'!C24 -> Google | B6: =SUM('Company Spending Data'!E4, 'Company Spending Data'!E8, 'Company Spending Data'!E12, 'Company Spending Data'!E16, 'Company Spending Data'!E20, 'Company Spending Data'!E24, 'Company Spending Data'!E28, 'Company Spending Data'!E32,) -> 1.4256309e+09 | C6: =SUM('Company Spending Data'!F4, 'Company Spending Data'!F8, 'Company Spending Data'!F12, 'Company Spending Data'!F16, 'Company Spending Data'!F20, 'Company Spending Data'!F24, 'Company Spending Data'!F28, 'Company Spending Data'!F32,) -> 1.5785515e+09 | D6: =SUM('Company Spending Data'!G4, 'Company Spending Data'!G8, 'Company Spending Data'!G12, 'Company Spending Data'!G16, 'Company Spending Data'!G20, 'Company Spending Data'!G24, 'Company Spending Data'!G28, 'Company Spending Data'!G32,) -> 3.803622e+09 | E6: =SUM('Company Spending Data'!H4, 'Company Spending Data'!H8, 'Company Spending Data'!H12, 'Company Spending Data'!H16, 'Company Spending Data'!H20, 'Company Spending Data'!H24, 'Company Spending Data'!H28, 'Company Spending Data'!H32,) -> 1.5321634e+09 | F6: =SUM(B6:E6) -> 8.3399679e+09
A7: ='[1]Quarterly Data'!C25 -> NVIDIA | B7: =SUM('Company Spending Data'!E5, 'Company Spending Data'!E9, 'Company Spending Data'!E13, 'Company Spending Data'!E17, 'Company Spending Data'!E21, 'Company Spending Data'!E25, 'Company Spending Data'!E29, 'Company Spending Data'!E33,) -> 7.5666906e+09 | C7: =SUM('Company Spending Data'!F5, 'Company Spending Data'!F9, 'Company Spending Data'!F13, 'Company Spending Data'!F17, 'Company Spending Data'!F21, 'Company Spending Data'!F25, 'Company Spending Data'!F29, 'Company Spending Data'!F33,) -> 8.5285304e+09 | D7: =SUM('Company Spending Data'!G5, 'Company Spending Data'!G9, 'Company Spending Data'!G13, 'Company Spending Data'!G17, 'Company Spending Data'!G21, 'Company Spending Data'!G25, 'Company Spending Data'!G29, 'Company Spending Data'!G33,) -> 3.2822721e+10 | E7: =SUM('Company Spending Data'!H5, 'Company Spending Data'!H9, 'Company Spending Data'!H13, 'Company Spending Data'!H17, 'Company Spending Data'!H21, 'Company Spending Data'!H25, 'Company Spending Data'!H29, 'Company Spending Data'!H33,) -> 5.2908622e+09 | F7: =SUM(B7:E7) -> 5.4208805e+10
A11: Industry Total
A13: Quarter | B13: Total Industry Cost (USD)
A14: Q1 2024 | B14: =SUM('Company Spending Data'!I2:I5) + 'Company Spending Data'!I34 -> 3.2356161e+09
A15: Q2 2024 | B15: =SUM('Company Spending Data'!I6:I9) + 'Company Spending Data'!I35 -> 4.2778195e+09
A16: Q3 2024 | B16: =SUM('Company Spending Data'!I10:I13) + 'Company Spending Data'!I36 -> 5.9882077e+09
A17: Q4 2024 | B17: =SUM('Company Spending Data'!I14:I17) + 'Company Spending Data'!I37 -> 8.5088587e+09
A18: Q1 2025 | B18: =SUM('Company Spending Data'!I18:I21) + 'Company Spending Data'!I38 -> 9.8632657e+09
A19: Q2 2025 | B19: =SUM('Company Spending Data'!I22:I25) + 'Company Spending Data'!I39 -> 1.0749339e+10
A20: Q3 2025 | B20: =SUM('Company Spending Data'!I26:I29) + 'Company Spending Data'!I340 -> 1.4233048e+10
A21: Q4 2025 | B21: =SUM('Company Spending Data'!I30:I33) + 'Company Spending Data'!I40 -> 1.7356948e+10
A23: All Quarters Total | B23: =SUM(B14:B22) -> 7.4213103e+10

Sheet Company Spending Data
A1: Designer | B1: Quarter | C1: Start Date | D1: End Date | E1: Logic Cost | F1: CoWoS Cost | G1: HBM Cost | H1: Auxiliary Cost | I1: Total Cost
A2: AMD | B2: Q1 2024 | C2: 2024-01-01 | D2: 2024-03-31 | E2: 25721836 | F2: 77212738 | G2: 2.1898619e+08 | H2: 17172825 | I2: =SUM(E2,F2,G2,H2) -> 3.3909358e+08
A3: Amazon | B3: Q1 2024 | C3: 2024-01-01 | D3: 2024-03-31 | E3: 12253701 | F3: 48831245 | G3: 99421726 | H3: 43101893 | I3: =SUM(E3,F3,G3,H3) -> 2.0360857e+08
A4: Google | B4: Q1 2024 | C4: 2024-01-01 | D4: 2024-03-31 | E4: 89422816 | F4: 1.263663e+08 | G4: 2.3828288e+08 | H4: 1.3518356e+08 | I4: =SUM(E4,F4,G4,H4) -> 5.8925555e+08
A5: NVIDIA | B5: Q1 2024 | C5: 2024-01-01 | D5: 2024-03-31 | E5: 3.3026652e+08 | F5: 3.5817163e+08 | G5: 1.1231171e+09 | H5: 2.9210314e+08 | I5: =SUM(E5,F5,G5,H5) -> 2.1036584e+09
A6: AMD | B6: Q2 2024 | C6: 2024-04-01 | D6: 2024-06-30 | E6: 39611323 | F6: 1.2438755e+08 | G6: 3.4528599e+08 | H6: 40557721 | I6: =SUM(E6,F6,G6,H6) -> 5.4984258e+08
A7: Amazon | B7: Q2 2024 | C7: 2024-04-01 | D7: 2024-06-30 | E7: 29252213 | F7: 66649907 | G7: 1.5707012e+08 | H7: 50330133 | I7: =SUM(E7,F7,G7,H7) -> 3.0330237e+08
A8: Google | B8: Q2 2024 | C8: 2024-04-01 | D8: 2024-06-30 | E8: 1.0556844e+08 | F8: 1.4155993e+08 | G8: 2.8706e+08 | H8: 1.4751511e+08 | I8: =SUM(E8,F8,G8,H8) -> 6.8170349e+08
A9: NVIDIA | B9: Q2 2024 | C9: 2024-04-01 | D9: 2024-06-30 | E9: 4.0728828e+08 | F9: 4.4295545e+08 | G9: 1.5238151e+09 | H9: 3.6891229e+08 | I9: =SUM(E9,F9,G9,H9) -> 2.7429711e+09
A10: AMD | B10: Q3 2024 | C10: 2024-07-01 | D10: 2024-09-30 | E10: 59542127 | F10: 1.8597016e+08 | G10: 5.1830625e+08 | H10: 58620661 | I10: =SUM(E10,F10,G10,H10) -> 8.224392e+08
A11: Amazon | B11: Q3 2024 | C11: 2024-07-01 | D11: 2024-09-30 | E11: 71475123 | F11: 1.1119192e+08 | G11: 3.0232644e+08 | H11: 68375411 | I11: =SUM(E11,F11,G11,H11) -> 5.5336889e+08
A12: Google | B12: Q3 2024 | C12: 2024-07-01 | D12: 2024-09-30 | E12: 1.3300287e+08 | F12: 1.6143416e+08 | G12: 3.1550898e+08 | H12: 1.628659e+08 | I12: =SUM(E12,F12,G12,H12) -> 7.7281191e+08
A13: NVIDIA | B13: Q3 2024 | C13: 2024-07-01 | D13: 2024-09-30 | E13: 5.5922416e+08 | F13: 6.151512e+08 | G13: 2.213545e+09 | H13: 4.5166735e+08 | I13: =SUM(E13,F13,G13,H13) -> 3.8395877e+09
... A33: NVIDIA | B33: Q4 2025 | C33: 2025-10-01 | D33: 2025-12-31 | E33: 1.8158508e+09 | F33: 1.9693246e+09 | G33: 8.5802364e+09 | H33: 1.066678e+09 | I33: =SUM(E33,F33,G33,H33) -> 1.343209e+10

Sheet Semiconductor Price Index
A1: Observation Date | B1: Producer Price Index
A2: 44562 | B2: 52.357
A3: 44593 | B3: 52.423
A4: 44621 | B4: 52.803
A5: 44652 | B5: 52.835
A6: 44682 | B6: 52.835
A7: 44713 | B7: 52.781
A8: 44743 | B8: 53.462
A9: 44774 | B9: 53.134
A10: 44805 | B10: 53.776
A11: 44835 | B11: 53.946
A12: 44866 | B12: 54.484
A13: 44896 | B13: 54.472
... A58: 46266 | B58: 50.521
